# 《帮金币的同学配环境》`2024-11-06`

- 创建了一个 `conda` 虚拟环境：`tf_gpu_env`
- 下载数据集：https://nlp.stanford.edu/projects/glove/
  - https://nlp.stanford.edu/data/glove.840B.300d.zip

- 跑起来之后遇到报错

```
Traceback (most recent call last):
  File "/run/media/neko/Archive_001/Archive/2024-11-06 帮同学配环境/CAUM-main/Code/main.py", line 49, in <module>
    model.fit(train_generator, epochs=5)
  File "/home/neko/.local/mambaforge/envs/tf_gpu_env/lib/python3.9/site-packages/keras/src/utils/traceback_utils.py", line 122, in error_handler
    raise e.with_traceback(filtered_tb) from None
  File "/home/neko/.local/mambaforge/envs/tf_gpu_env/lib/python3.9/site-packages/tensorflow/python/data/ops/from_generator_op.py", line 124, in _from_generator
    raise TypeError(f"`output_signature` must contain objects that are "
TypeError: `output_signature` must contain objects that are subclass of `tf.TypeSpec` but found <class 'list'> which is not.
```

- 看一眼：`/home/neko/.local/mambaforge/envs/tf_gpu_env/lib/python3.9/site-packages/tensorflow/python/data/ops/from_generator_op.py`

- 试图通过装饰器注入解决问题

```python

train_generator_raw = get_hir_train_generator(news_info, train_user['click'], train_user_id, train_sess, train_label, 64)

def log_print(msg): # 输出内容到日志
    fp = open("log.txt", "a")
    fp.write("[%13.6f] %s\n" % (time.time(), msg))
    sys.stderr.write("\033[1;31m[%13.6f] %s\033[0m\n" % (time.time(), msg))
    fp.close()

def generator_decorator(gen_func):
    def wrapper(*args, **kwargs):
        log_print("Generator started") # 调用生成器函数
        gen = gen_func(*args, **kwargs)
        try:
            while True: # 从生成器中获取下一个值
                value = next(gen)
                log_print(f"Yielding: {value}")
                yield value
        except StopIteration:
            log_print("Generator finished") # 捕获生成器的结束
            return gen.gi_frame.f_locals.get('return_value', None)
    return wrapper

train_generator = generator_decorator(train_generator_raw)
```

- 但是发现装饰器压根就没被调用过
- 把 generator.py 中的函数进行了修改
  - 基本猜想来自于：https://stackoverflow.com/questions/78138687/output-signature-must-contain-objects-that-are-subclass-of-tf-typespec-but-f

```python
    def __getitem__(self, idx):
        start = idx*self.batch_size
        ed = (idx+1)*self.batch_size
        if ed> self.ImpNum:
            ed = self.ImpNum
        label = self.label[start:ed]
        
        doc_ids = self.doc_id[start:ed]
        title= self.__get_news(doc_ids)
        
        user_ids = self.user_id[start:ed]
        clicked_ids = self.clicked_news[user_ids]
        user_title = self.__get_news(clicked_ids)

        return ((title, user_title),(label, )) # 主要是这里用 tuple 不要用 list
```

- 遇到了新的报错

```python
Epoch 1/5
Traceback (most recent call last):
  File "/run/media/neko/Archive_001/Archive/2024-11-06 帮同学配环境/CAUM-main/Code/main.py", line 51, in <module>
    model.fit(train_generator, epochs=5)
  File "/home/neko/.local/mambaforge/envs/tf_gpu_env/lib/python3.9/site-packages/keras/src/utils/traceback_utils.py", line 122, in error_handler
    raise e.with_traceback(filtered_tb) from None
  File "/run/media/neko/Archive_001/Archive/2024-11-06 帮同学配环境/CAUM-main/Code/Models.py", line 62, in call
    Q_seq = K.dot(Q_seq, self.WQ)
AttributeError: Exception encountered when calling Attention.call().

module 'keras.api.backend' has no attribute 'dot'

Arguments received by Attention.call():
  • x=['tf.Tensor(shape=(None, 5, 100), dtype=float32)', 'tf.Tensor(shape=(None, 5, 100), dtype=float32)', 'tf.Tensor(shape=(None, 5, 100), dtype=float32)']
```

- 又是一波 stackoverflow
  - https://stackoverflow.com/questions/78851440/module-keras-backend-has-no-attribute-dot

